Traceback (most recent call last):
  File "/home/pat/anaconda3/lib/python3.9/site-packages/jupyter_cache/executors/utils.py", line 58, in single_nb_execution
    executenb(
  File "/home/pat/anaconda3/lib/python3.9/site-packages/nbclient/client.py", line 1112, in execute
    return NotebookClient(nb=nb, resources=resources, km=km, **kwargs).execute()
  File "/home/pat/anaconda3/lib/python3.9/site-packages/nbclient/util.py", line 74, in wrapped
    return just_run(coro(*args, **kwargs))
  File "/home/pat/anaconda3/lib/python3.9/site-packages/nbclient/util.py", line 53, in just_run
    return loop.run_until_complete(coro)
  File "/home/pat/anaconda3/lib/python3.9/asyncio/base_events.py", line 642, in run_until_complete
    return future.result()
  File "/home/pat/anaconda3/lib/python3.9/site-packages/nbclient/client.py", line 553, in async_execute
    await self.async_execute_cell(
  File "/home/pat/anaconda3/lib/python3.9/site-packages/nbclient/client.py", line 857, in async_execute_cell
    self._check_raise_for_error(cell, exec_reply)
  File "/home/pat/anaconda3/lib/python3.9/site-packages/nbclient/client.py", line 760, in _check_raise_for_error
    raise CellExecutionError.from_cell_and_msg(cell, exec_reply_content)
nbclient.exceptions.CellExecutionError: An error occurred while executing the following cell:
------------------
#Demonstrate UNSAFE dictionary key access method
for key in ['x', 'y', 'z', 'w']:

    # Unsafe method: direct indexing raises KeyError if key doesn't exist
    # This will work fine for 'x', 'y', 'z' but will raise a KeyError for 'w'
    # The program will crash when it tries to access the non-existent key 'w'
    print(third_dict[key])  # Returns an error for w
------------------

[0;31m---------------------------------------------------------------------------[0m
[0;31mKeyError[0m                                  Traceback (most recent call last)
[0;32m/tmp/ipykernel_35503/2772980581.py[0m in [0;36m<module>[0;34m[0m
[1;32m      5[0m     [0;31m# This will work fine for 'x', 'y', 'z' but will raise a KeyError for 'w'[0m[0;34m[0m[0;34m[0m[0m
[1;32m      6[0m     [0;31m# The program will crash when it tries to access the non-existent key 'w'[0m[0;34m[0m[0;34m[0m[0m
[0;32m----> 7[0;31m     [0mprint[0m[0;34m([0m[0mthird_dict[0m[0;34m[[0m[0mkey[0m[0;34m][0m[0;34m)[0m  [0;31m# Returns an error for w[0m[0;34m[0m[0;34m[0m[0m
[0m
[0;31mKeyError[0m: 'w'
KeyError: 'w'

